<?xml version="1.0" encoding="utf-8"?>
<!-- This URDF was automatically created by SolidWorks to URDF Exporter! Originally created by Stephen Brawner (brawner@gmail.com) 
     Commit Version: 1.6.0-4-g7f85cfe  Build Version: 1.6.7995.38578
     For more information, please see http://wiki.ros.org/sw_urdf_exporter -->
<robot
  name="rohand_left">
  <link
    name="base_link">
    <inertial>
      <origin
        xyz="-0.0487820914808079 0.00265859985480459 -0.000133621504108892"
        rpy="0 0 0" />
      <mass
        value="0.0518221802910333" />
      <inertia
        ixx="1.90439263186917E-05"
        ixy="9.03564771207103E-07"
        ixz="1.72175948368984E-06"
        iyy="2.43365876797143E-05"
        iyz="4.70653917629048E-07"
        izz="3.58010333896549E-05" />
    </inertial>
    <visual>
      <origin
        xyz="0 0 0"
        rpy="0 0 0" />
      <geometry>
        <mesh
          filename="package://rohand_urdf_ros2/meshes_l//base_link.STL" />
      </geometry>
      <material
        name="">
        <color
          rgba="1 1 1 1" />
      </material>
    </visual>
    <collision>
      <origin
        xyz="0 0 0"
        rpy="0 0 0" />
      <geometry>
        <mesh
          filename="package://rohand_urdf_ros2/meshes_l//base_link.STL" />
      </geometry>
    </collision>
  </link>
  <link
    name="if_slider_link">
    <inertial>
      <origin
        xyz="-0.00314570108168869 2.75882189600118E-07 -4.84121109910543E-09"
        rpy="0 0 0" />
      <mass
        value="0.000191988555317022" />
      <inertia
        ixx="1.26509405946619E-09"
        ixy="1.584320294311E-13"
        ixz="1.05293553143857E-15"
        iyy="1.58290667016945E-09"
        iyz="3.04767495758576E-11"
        izz="1.9298815825818E-09" />
    </inertial>
    <visual>
      <origin
        xyz="0 0 0"
        rpy="0 0 0" />
      <geometry>
        <mesh
          filename="package://rohand_urdf_ros2/meshes_l//if_slider_link.STL" />
      </geometry>
      <material
        name="">
        <color
          rgba="1 1 1 1" />
      </material>
    </visual>
    <collision>
      <origin
        xyz="0 0 0"
        rpy="0 0 0" />
      <geometry>
        <mesh
          filename="package://rohand_urdf_ros2/meshes_l//if_slider_link.STL" />
      </geometry>
    </collision>
  </link>
  <joint
    name="if_slider_link"
    type="prismatic">
    <origin
      xyz="-0.093141599200405 0.0283933334278235 -0.0060810126904691"
      rpy="0 0 -0.0829795346970403" />
    <parent
      link="base_link" />
    <child
      link="if_slider_link" />
    <axis
      xyz="1 0 0" />
    <limit
      lower="-0.003"
      upper="0.016"
      effort="0"
      velocity="0" />
  </joint>
  <link
    name="if_slider_abpart_link">
    <inertial>
      <origin
        xyz="-0.0102575899823259 6.32254656893205E-08 -0.00167499723063989"
        rpy="0 0 0" />
      <mass
        value="0.000457378818734687" />
      <inertia
        ixx="2.48984483431531E-09"
        ixy="-1.07002031944009E-13"
        ixz="-3.31080655152953E-09"
        iyy="1.65925835165026E-08"
        iyz="-5.59245259075753E-14"
        izz="1.63812574276271E-08" />
    </inertial>
    <visual>
      <origin
        xyz="0 0 0"
        rpy="0 0 0" />
      <geometry>
        <mesh
          filename="package://rohand_urdf_ros2/meshes_l//if_slider_abpart_link.STL" />
      </geometry>
      <material
        name="">
        <color
          rgba="1 1 1 1" />
      </material>
    </visual>
    <collision>
      <origin
        xyz="0 0 0"
        rpy="0 0 0" />
      <geometry>
        <mesh
          filename="package://rohand_urdf_ros2/meshes_l//if_slider_abpart_link.STL" />
      </geometry>
    </collision>
  </link>
  <joint
    name="if_slider_abpart_link"
    type="continuous">
    <origin
      xyz="-0.00717233182793718 0 0"
      rpy="-0.0872362806506897 -0.00722294993772634 0.000631700989182225" />
    <parent
      link="if_slider_link" />
    <child
      link="if_slider_abpart_link" />
    <axis
      xyz="0 1 0" />
  </joint>
  <link
    name="if_proximal_link">
    <inertial>
      <origin
        xyz="-0.0160191806570643 -9.85142243230056E-05 -0.00754046987606504"
        rpy="0 0 0" />
      <mass
        value="0.00155055071205295" />
      <inertia
        ixx="6.86607391836046E-08"
        ixy="6.40072418115391E-13"
        ixz="-2.71259693334484E-08"
        iyy="1.54822273521611E-07"
        iyz="2.47495564284397E-12"
        izz="1.62362361694252E-07" />
    </inertial>
    <visual>
      <origin
        xyz="0 0 0"
        rpy="0 0 0" />
      <geometry>
        <mesh
          filename="package://rohand_urdf_ros2/meshes_l//if_proximal_link.STL" />
      </geometry>
      <material
        name="">
        <color
          rgba="1 1 1 1" />
      </material>
    </visual>
    <collision>
      <origin
        xyz="0 0 0"
        rpy="0 0 0" />
      <geometry>
        <mesh
          filename="package://rohand_urdf_ros2/meshes_l//if_proximal_link.STL" />
      </geometry>
    </collision>
  </link>
  <joint
    name="if_proximal_link"
    type="continuous">
    <origin
      xyz="-0.112691326549452 0.0308429886174686 0.00248020890615535"
      rpy="-0.0873108596933026 -0.00722906372465864 -0.0823986361856106" />
    <parent
      link="base_link" />
    <child
      link="if_proximal_link" />
    <axis
      xyz="0 1 0" />
  </joint>
  <link
    name="if_distal_link">
    <inertial>
      <origin
        xyz="-0.0140538112764014 -9.47215516734282E-05 -0.0187678244897316"
        rpy="0 0 0" />
      <mass
        value="0.00416343809392657" />
      <inertia
        ixx="3.83568682794517E-07"
        ixy="3.63718673744345E-12"
        ixz="-2.50539432666401E-07"
        iyy="5.74332962728061E-07"
        iyz="5.30242000028538E-12"
        izz="2.66484932765124E-07" />
    </inertial>
    <visual>
      <origin
        xyz="0 0 0"
        rpy="0 0 0" />
      <geometry>
        <mesh
          filename="package://rohand_urdf_ros2/meshes_l//if_distal_link.STL" />
      </geometry>
      <material
        name="">
        <color
          rgba="1 1 1 1" />
      </material>
    </visual>
    <collision>
      <origin
        xyz="0 0 0"
        rpy="0 0 0" />
      <geometry>
        <mesh
          filename="package://rohand_urdf_ros2/meshes_l//if_distal_link.STL" />
      </geometry>
    </collision>
  </link>
  <joint
    name="if_distal_link"
    type="continuous">
    <origin
      xyz="-0.0340605619485064 0 -0.0114050053411428"
      rpy="2.57804029017016E-05 0 -0.000101940406116998" />
    <parent
      link="if_proximal_link" />
    <child
      link="if_distal_link" />
    <axis
      xyz="0 1 0" />
  </joint>
  <link
    name="if_connecting_link">
    <inertial>
      <origin
        xyz="-0.0115270623875577 -9.99155076033577E-05 -0.012278088629305"
        rpy="0 0 0" />
      <mass
        value="0.00024711756965943" />
      <inertia
        ixx="1.56882416541916E-08"
        ixy="9.80592910395524E-16"
        ixz="-1.64059842022437E-08"
        iyy="3.38395395293219E-08"
        iyz="7.54686720390201E-16"
        izz="1.81924842076912E-08" />
    </inertial>
    <visual>
      <origin
        xyz="0 0 0"
        rpy="0 0 0" />
      <geometry>
        <mesh
          filename="package://rohand_urdf_ros2/meshes_l//if_connecting_link.STL" />
      </geometry>
      <material
        name="">
        <color
          rgba="1 1 1 1" />
      </material>
    </visual>
    <collision>
      <origin
        xyz="0 0 0"
        rpy="0 0 0" />
      <geometry>
        <mesh
          filename="package://rohand_urdf_ros2/meshes_l//if_connecting_link.STL" />
      </geometry>
    </collision>
  </link>
  <joint
    name="if_connecting_link"
    type="continuous">
    <origin
      xyz="-0.120051727129588 0.0318672321540881 0.00686116990260903"
      rpy="-0.0872898030131476 -0.00722733820087602 -0.0823989405972364" />
    <parent
      link="base_link" />
    <child
      link="if_connecting_link" />
    <axis
      xyz="0 1 0" />
  </joint>
  <link
    name="mf_slider_link">
    <inertial>
      <origin
        xyz="-0.00314570080755083 2.77039370475546E-07 1.8793232185732E-08"
        rpy="0 0 0" />
      <mass
        value="0.000191988548040141" />
      <inertia
        ixx="1.26509400193903E-09"
        ixy="1.58406977126282E-13"
        ixz="1.45881888003919E-14"
        iyy="1.58024980969162E-09"
        iyz="-7.83790018603535E-14"
        izz="1.93253773882945E-09" />
    </inertial>
    <visual>
      <origin
        xyz="0 0 0"
        rpy="0 0 0" />
      <geometry>
        <mesh
          filename="package://rohand_urdf_ros2/meshes_l//mf_slider_link.STL" />
      </geometry>
      <material
        name="">
        <color
          rgba="1 1 1 1" />
      </material>
    </visual>
    <collision>
      <origin
        xyz="0 0 0"
        rpy="0 0 0" />
      <geometry>
        <mesh
          filename="package://rohand_urdf_ros2/meshes_l//mf_slider_link.STL" />
      </geometry>
    </collision>
  </link>
  <joint
    name="mf_slider_link"
    type="prismatic">
    <origin
      xyz="-0.095789 0.010504 -0.001815"
      rpy="0 -0.00010039 -0.01323" />
    <parent
      link="base_link" />
    <child
      link="mf_slider_link" />
    <axis
      xyz="1 0 0" />
    <limit
      lower="-0.003"
      upper="0.016"
      effort="0"
      velocity="0" />
  </joint>
  <link
    name="mf_slider_abpart_link">
    <inertial>
      <origin
        xyz="-0.0102177751127501 6.32373028212896E-08 -0.00190285084370342"
        rpy="0 0 0" />
      <mass
        value="0.000457378814740125" />
      <inertia
        ixx="2.64404249097883E-09"
        ixy="-1.05767936992906E-13"
        ixz="-3.61658487093865E-09"
        iyy="1.65925833113347E-08"
        iyz="-5.82951253195829E-14"
        izz="1.62270595534221E-08" />
    </inertial>
    <visual>
      <origin
        xyz="0 0 0"
        rpy="0 0 0" />
      <geometry>
        <mesh
          filename="package://rohand_urdf_ros2/meshes_l//mf_slider_abpart_link.STL" />
      </geometry>
      <material
        name="">
        <color
          rgba="1 1 1 1" />
      </material>
    </visual>
    <collision>
      <origin
        xyz="0 0 0"
        rpy="0 0 0" />
      <geometry>
        <mesh
          filename="package://rohand_urdf_ros2/meshes_l//mf_slider_abpart_link.STL" />
      </geometry>
    </collision>
  </link>
  <joint
    name="mf_slider_abpart_link"
    type="continuous">
    <origin
      xyz="-0.0071723 0 0"
      rpy="-6.2891E-05 9.9576E-05 0" />
    <parent
      link="mf_slider_link" />
    <child
      link="mf_slider_abpart_link" />
    <axis
      xyz="0 1 0" />
  </joint>
  <link
    name="mf_proximal_link">
    <inertial>
      <origin
        xyz="0.0383189383157601 -0.000510921119742665 -0.0158668059695368"
        rpy="0 0 0" />
      <mass
        value="0.102110343610594" />
      <inertia
        ixx="9.82030707897617E-05"
        ixy="4.89564456391385E-06"
        ixz="-3.61758386657043E-05"
        iyy="0.000271614172373814"
        iyz="2.12855765917574E-05"
        izz="0.00031052903399449" />
    </inertial>
    <visual>
      <origin
        xyz="0 0 0"
        rpy="0 0 0" />
      <geometry>
        <mesh
          filename="package://rohand_urdf_ros2/meshes_l//mf_proximal_link.STL" />
      </geometry>
      <material
        name="">
        <color
          rgba="1 1 1 1" />
      </material>
    </visual>
    <collision>
      <origin
        xyz="0 0 0"
        rpy="0 0 0" />
      <geometry>
        <mesh
          filename="package://rohand_urdf_ros2/meshes_l//mf_proximal_link.STL" />
      </geometry>
    </collision>
  </link>
  <joint
    name="mf_proximal_link"
    type="continuous">
    <origin
      xyz="-0.11597 0.010647 0.0067882"
      rpy="0 0 -0.013245" />
    <parent
      link="base_link" />
    <child
      link="mf_proximal_link" />
    <axis
      xyz="0 1 0" />
  </joint>
  <link
    name="mf_distal_link">
    <inertial>
      <origin
        xyz="-0.014267738129629 9.50657057813085E-05 -0.0186055678442516"
        rpy="0 0 0" />
      <mass
        value="0.0041634139178577" />
      <inertia
        ixx="3.77812748746114E-07"
        ixy="2.94193547959992E-12"
        ixz="-2.51812168882212E-07"
        iyy="5.74328431362478E-07"
        iyz="4.2495236681414E-12"
        izz="2.72235839391315E-07" />
    </inertial>
    <visual>
      <origin
        xyz="0 0 0"
        rpy="0 0 0" />
      <geometry>
        <mesh
          filename="package://rohand_urdf_ros2/meshes_l//mf_distal_link.STL" />
      </geometry>
      <material
        name="">
        <color
          rgba="1 1 1 1" />
      </material>
    </visual>
    <collision>
      <origin
        xyz="0 0 0"
        rpy="0 0 0" />
      <geometry>
        <mesh
          filename="package://rohand_urdf_ros2/meshes_l//mf_distal_link.STL" />
      </geometry>
    </collision>
  </link>
  <joint
    name="mf_distal_link"
    type="continuous">
    <origin
      xyz="-0.038293 0 -0.014673"
      rpy="0 0 0" />
    <parent
      link="mf_proximal_link" />
    <child
      link="mf_distal_link" />
    <axis
      xyz="0 1 0" />
  </joint>
  <link
    name="mf_connecting_link">
    <inertial>
      <origin
        xyz="-0.0133612107724269 9.99470684219742E-05 -0.0138042394479139"
        rpy="0 0 0" />
      <mass
        value="0.000270250689971117" />
      <inertia
        ixx="2.16828904856653E-08"
        ixy="-1.1870806262578E-16"
        ixz="-2.34671548290617E-08"
        iyy="4.8145498010029E-08"
        iyz="-1.34357377737992E-16"
        izz="2.65076490844574E-08" />
    </inertial>
    <visual>
      <origin
        xyz="0 0 0"
        rpy="0 0 0" />
      <geometry>
        <mesh
          filename="package://rohand_urdf_ros2/meshes_l//mf_connecting_link.STL" />
      </geometry>
      <material
        name="">
        <color
          rgba="1 1 1 1" />
      </material>
    </visual>
    <collision>
      <origin
        xyz="0 0 0"
        rpy="0 0 0" />
      <geometry>
        <mesh
          filename="package://rohand_urdf_ros2/meshes_l//mf_connecting_link.STL" />
      </geometry>
    </collision>
  </link>
  <joint
    name="mf_connecting_link"
    type="continuous">
    <origin
      xyz="-0.12339 0.010769 0.011188"
      rpy="2.1055E-05 0 -0.013245" />
    <parent
      link="base_link" />
    <child
      link="mf_connecting_link" />
    <axis
      xyz="0 1 0" />
  </joint>
  <link
    name="rf_slider_link">
    <inertial>
      <origin
        xyz="-0.00314570113903062 2.69888921692121E-07 2.10339454508393E-08"
        rpy="0 0 0" />
      <mass
        value="0.000191988559777486" />
      <inertia
        ixx="1.26509406688287E-09"
        ixy="1.55948558110338E-13"
        ixz="1.5769502713154E-14"
        iyy="1.58025014270713E-09"
        iyz="-7.83849634005999E-14"
        izz="1.93253814782508E-09" />
    </inertial>
    <visual>
      <origin
        xyz="0 0 0"
        rpy="0 0 0" />
      <geometry>
        <mesh
          filename="package://rohand_urdf_ros2/meshes_l//rf_slider_link.STL" />
      </geometry>
      <material
        name="">
        <color
          rgba="1 1 1 1" />
      </material>
    </visual>
    <collision>
      <origin
        xyz="0 0 0"
        rpy="0 0 0" />
      <geometry>
        <mesh
          filename="package://rohand_urdf_ros2/meshes_l//rf_slider_link.STL" />
      </geometry>
    </collision>
  </link>
  <joint
    name="rf_slider_link"
    type="prismatic">
    <origin
      xyz="-0.093265347397978 -0.00813438556869404 -0.00255981174590743"
      rpy="0 -9.50818117190785E-05 0.0565869121559373" />
    <parent
      link="base_link" />
    <child
      link="rf_slider_link" />
    <axis
      xyz="1 0 0" />
    <limit
      lower="-0.003"
      upper="0.016"
      effort="0"
      velocity="0" />
  </joint>
  <link
    name="rf_slider_abpart_link">
    <inertial>
      <origin
        xyz="-0.0102282712592658 6.32805208199139E-08 -0.00184560051893905"
        rpy="0 0 0" />
      <mass
        value="0.000457378802308313" />
      <inertia
        ixx="2.60396268815709E-09"
        ixy="-1.06217783180531E-13"
        ixz="-3.5402930189721E-09"
        iyy="1.65925827365102E-08"
        iyz="-5.77022634025394E-14"
        izz="1.62671387284969E-08" />
    </inertial>
    <visual>
      <origin
        xyz="0 0 0"
        rpy="0 0 0" />
      <geometry>
        <mesh
          filename="package://rohand_urdf_ros2/meshes_l//rf_slider_abpart_link.STL" />
      </geometry>
      <material
        name="">
        <color
          rgba="1 1 1 1" />
      </material>
    </visual>
    <collision>
      <origin
        xyz="0 0 0"
        rpy="0 0 0" />
      <geometry>
        <mesh
          filename="package://rohand_urdf_ros2/meshes_l//rf_slider_abpart_link.STL" />
      </geometry>
    </collision>
  </link>
  <joint
    name="rf_slider_abpart_link"
    type="continuous">
    <origin
      xyz="-0.00717233182914902 0 0"
      rpy="-6.30032465600259E-05 9.89558911798051E-05 0" />
    <parent
      link="rf_slider_link" />
    <child
      link="rf_slider_abpart_link" />
    <axis
      xyz="0 1 0" />
  </joint>
  <link
    name="rf_proximal_link">
    <inertial>
      <origin
        xyz="-0.0157473172062689 -9.85176942848373E-05 -0.00809296750089365"
        rpy="0 0 0" />
      <mass
        value="0.00155057954584347" />
      <inertia
        ixx="7.06600062354648E-08"
        ixy="9.80911825920864E-13"
        ixz="-3.03177266166378E-08"
        iyy="1.54825000259125E-07"
        iyz="2.70998235657128E-12"
        izz="1.60366935463804E-07" />
    </inertial>
    <visual>
      <origin
        xyz="0 0 0"
        rpy="0 0 0" />
      <geometry>
        <mesh
          filename="package://rohand_urdf_ros2/meshes_l//rf_proximal_link.STL" />
      </geometry>
      <material
        name="">
        <color
          rgba="1 1 1 1" />
      </material>
    </visual>
    <collision>
      <origin
        xyz="0 0 0"
        rpy="0 0 0" />
      <geometry>
        <mesh
          filename="package://rohand_urdf_ros2/meshes_l//rf_proximal_link.STL" />
      </geometry>
    </collision>
  </link>
  <joint
    name="rf_proximal_link"
    type="continuous">
    <origin
      xyz="-0.113236510954413 -0.00919405777842235 0.00603824652583962"
      rpy="0 0 0.056602255215157" />
    <parent
      link="base_link" />
    <child
      link="rf_proximal_link" />
    <axis
      xyz="0 1 0" />
  </joint>
  <link
    name="rf_distal_link">
    <inertial>
      <origin
        xyz="-0.0127271231716963 -9.38053229480387E-05 -0.0196845523638123"
        rpy="0 0 0" />
      <mass
        value="0.00416255068346841" />
      <inertia
        ixx="4.17201194420604E-07"
        ixy="-1.25234262806125E-12"
        ixz="-2.40009202128589E-07"
        iyy="5.740592232242E-07"
        iyz="-5.32325459385579E-12"
        izz="2.32587484901898E-07" />
    </inertial>
    <visual>
      <origin
        xyz="0 0 0"
        rpy="0 0 0" />
      <geometry>
        <mesh
          filename="package://rohand_urdf_ros2/meshes_l//rf_distal_link.STL" />
      </geometry>
      <material
        name="">
        <color
          rgba="1 1 1 1" />
      </material>
    </visual>
    <collision>
      <origin
        xyz="0 0 0"
        rpy="0 0 0" />
      <geometry>
        <mesh
          filename="package://rohand_urdf_ros2/meshes_l//rf_distal_link.STL" />
      </geometry>
    </collision>
  </link>
  <joint
    name="rf_distal_link"
    type="continuous">
    <origin
      xyz="-0.0336433389681109 0 -0.0125825979097555"
      rpy="2.93098936036424E-05 0 -0.0001009823092024" />
    <parent
      link="rf_proximal_link" />
    <child
      link="rf_distal_link" />
    <axis
      xyz="0 1 0" />
  </joint>
  <link
    name="rf_connecting_link">
    <inertial>
      <origin
        xyz="-0.0110232841099943 -9.99168446228355E-05 -0.0127323120354629"
        rpy="0 0 0" />
      <mass
        value="0.000247117666203693" />
      <inertia
        ixx="1.70125353501729E-08"
        ixy="9.85209394904434E-16"
        ixz="-1.64535404358962E-08"
        iyy="3.38395389705052E-08"
        iyz="8.23904781414684E-16"
        izz="1.68681899685106E-08" />
    </inertial>
    <visual>
      <origin
        xyz="0 0 0"
        rpy="0 0 0" />
      <geometry>
        <mesh
          filename="package://rohand_urdf_ros2/meshes_l//rf_connecting_link.STL" />
      </geometry>
      <material
        name="">
        <color
          rgba="1 1 1 1" />
      </material>
    </visual>
    <collision>
      <origin
        xyz="0 0 0"
        rpy="0 0 0" />
      <geometry>
        <mesh
          filename="package://rohand_urdf_ros2/meshes_l//rf_connecting_link.STL" />
      </geometry>
    </collision>
  </link>
  <joint
    name="rf_connecting_link"
    type="continuous">
    <origin
      xyz="-0.120646556392296 -0.00958718365665331 0.0104375725753832"
      rpy="2.10205544385047E-05 0 0.0566022572146075" />
    <parent
      link="base_link" />
    <child
      link="rf_connecting_link" />
    <axis
      xyz="0 1 0" />
  </joint>
  <link
    name="lf_slider_link">
    <inertial>
      <origin
        xyz="-0.00314570130825416 2.68667008126999E-07 4.40144759033742E-08"
        rpy="0 0 0" />
      <mass
        value="0.000191988562577953" />
      <inertia
        ixx="1.26509410685735E-09"
        ixy="1.54491784962314E-13"
        ixz="2.90605731080213E-14"
        iyy="1.58294475425644E-09"
        iyz="-3.06914701986574E-11"
        izz="1.92984403518941E-09" />
    </inertial>
    <visual>
      <origin
        xyz="0 0 0"
        rpy="0 0 0" />
      <geometry>
        <mesh
          filename="package://rohand_urdf_ros2/meshes_l//lf_slider_link.STL" />
      </geometry>
      <material
        name="">
        <color
          rgba="1 1 1 1" />
      </material>
    </visual>
    <collision>
      <origin
        xyz="0 0 0"
        rpy="0 0 0" />
      <geometry>
        <mesh
          filename="package://rohand_urdf_ros2/meshes_l//lf_slider_link.STL" />
      </geometry>
    </collision>
  </link>
  <joint
    name="lf_slider_link"
    type="prismatic">
    <origin
      xyz="-0.089576643926692 -0.0262308897592081 -0.00507914898073518"
      rpy="0 -8.27044529585942E-05 0.118308341349328" />
    <parent
      link="base_link" />
    <child
      link="lf_slider_link" />
    <axis
      xyz="1 0 0" />
    <limit
      lower="-0.003"
      upper="0.016"
      effort="0"
      velocity="0" />
  </joint>
  <link
    name="lf_slider_abpart_link">
    <inertial>
      <origin
        xyz="-0.0102365548260327 6.32818707713145E-08 -0.00179908852586315"
        rpy="0 0 0" />
      <mass
        value="0.000457378802064142" />
      <inertia
        ixx="2.5720603050325E-09"
        ixy="-1.06480570424085E-13"
        ixz="-3.47804098038904E-09"
        iyy="1.65925827410743E-08"
        iyz="-5.72165626982387E-14"
        izz="1.62990411139413E-08" />
    </inertial>
    <visual>
      <origin
        xyz="0 0 0"
        rpy="0 0 0" />
      <geometry>
        <mesh
          filename="package://rohand_urdf_ros2/meshes_l//lf_slider_abpart_link.STL" />
      </geometry>
      <material
        name="">
        <color
          rgba="1 1 1 1" />
      </material>
    </visual>
    <collision>
      <origin
        xyz="0 0 0"
        rpy="0 0 0" />
      <geometry>
        <mesh
          filename="package://rohand_urdf_ros2/meshes_l//lf_slider_abpart_link.STL" />
      </geometry>
    </collision>
  </link>
  <joint
    name="lf_slider_abpart_link"
    type="continuous">
    <origin
      xyz="-0.00717233182992167 0 0"
      rpy="0.087286192987255 -0.0102383843018635 -0.000895930220605248" />
    <parent
      link="lf_slider_link" />
    <child
      link="lf_slider_abpart_link" />
    <axis
      xyz="0 1 0" />
  </joint>
  <link
    name="lf_proximal_link">
    <inertial>
      <origin
        xyz="-0.0140889603148996 0.000100219366981475 -0.00739779637681989"
        rpy="0 0 0" />
      <mass
        value="0.00136673401761359" />
      <inertia
        ixx="6.2312379017895E-08"
        ixy="-5.30007498690513E-13"
        ixz="-2.07728788478545E-08"
        iyy="1.12813046078577E-07"
        iyz="-3.85122175038345E-13"
        izz="1.20866210662174E-07" />
    </inertial>
    <visual>
      <origin
        xyz="0 0 0"
        rpy="0 0 0" />
      <geometry>
        <mesh
          filename="package://rohand_urdf_ros2/meshes_l//lf_proximal_link.STL" />
      </geometry>
      <material
        name="">
        <color
          rgba="1 1 1 1" />
      </material>
    </visual>
    <collision>
      <origin
        xyz="0 0 0"
        rpy="0 0 0" />
      <geometry>
        <mesh
          filename="package://rohand_urdf_ros2/meshes_l//lf_proximal_link.STL" />
      </geometry>
    </collision>
  </link>
  <joint
    name="lf_proximal_link"
    type="continuous">
    <origin
      xyz="-0.10947 -0.02946 0.0034771"
      rpy="0.087223 -0.010327 0.11755" />
    <parent
      link="base_link" />
    <child
      link="lf_proximal_link" />
    <axis
      xyz="0 1 0" />
  </joint>
  <link
    name="lf_distal_link">
    <inertial>
      <origin
        xyz="-0.00834849665142492 -0.000122866143159286 -0.0140829185600047"
        rpy="0 0 0" />
      <mass
        value="0.00263003416842098" />
      <inertia
        ixx="1.24027183170854E-07"
        ixy="-6.0832682379491E-10"
        ixz="-5.50957176664759E-08"
        iyy="1.53209583285237E-07"
        iyz="-1.07170470476068E-09"
        izz="7.25224471700782E-08" />
    </inertial>
    <visual>
      <origin
        xyz="0 0 0"
        rpy="0 0 0" />
      <geometry>
        <mesh
          filename="package://rohand_urdf_ros2/meshes_l//lf_distal_link.STL" />
      </geometry>
      <material
        name="">
        <color
          rgba="1 1 1 1" />
      </material>
    </visual>
    <collision>
      <origin
        xyz="0 0 0"
        rpy="0 0 0" />
      <geometry>
        <mesh
          filename="package://rohand_urdf_ros2/meshes_l//lf_distal_link.STL" />
      </geometry>
    </collision>
  </link>
  <joint
    name="lf_distal_link"
    type="continuous">
    <origin
      xyz="-0.029737 5.0315E-05 -0.011632"
      rpy="2.1055E-05 0 0" />
    <parent
      link="lf_proximal_link" />
    <child
      link="lf_distal_link" />
    <axis
      xyz="0 1 0" />
  </joint>
  <link
    name="lf_connecting_link">
    <inertial>
      <origin
        xyz="-0.00897984228217096 9.99101180365961E-05 -0.011993683724239"
        rpy="0 0 0" />
      <mass
        value="0.000221227665967327" />
      <inertia
        ixx="1.44106276095498E-08"
        ixy="4.45135844673142E-16"
        ixz="-1.20035920785773E-08"
        iyy="2.51147372461721E-08"
        iyz="3.33903046055941E-16"
        izz="1.07409809590346E-08" />
    </inertial>
    <visual>
      <origin
        xyz="0 0 0"
        rpy="0 0 0" />
      <geometry>
        <mesh
          filename="package://rohand_urdf_ros2/meshes_l//lf_connecting_link.STL" />
      </geometry>
      <material
        name="">
        <color
          rgba="1 1 1 1" />
      </material>
    </visual>
    <collision>
      <origin
        xyz="0 0 0"
        rpy="0 0 0" />
      <geometry>
        <mesh
          filename="package://rohand_urdf_ros2/meshes_l//lf_connecting_link.STL" />
      </geometry>
    </collision>
  </link>
  <joint
    name="lf_connecting_link"
    type="continuous">
    <origin
      xyz="-0.11679 -0.030717 0.0078597"
      rpy="0.087244 -0.01033 0.11755" />
    <parent
      link="base_link" />
    <child
      link="lf_connecting_link" />
    <axis
      xyz="0 1 0" />
  </joint>
  <link
    name="th_root_link">
    <inertial>
      <origin
        xyz="0.00191344367122664 0.00533360564246911 -0.0020687280213202"
        rpy="0 0 0" />
      <mass
        value="0.0021989478617719" />
      <inertia
        ixx="1.74016193932666E-07"
        ixy="5.93611655561927E-08"
        ixz="-4.97756456061674E-09"
        iyy="1.46354399695497E-07"
        iyz="1.16059679999205E-08"
        izz="1.72874089425251E-07" />
    </inertial>
    <visual>
      <origin
        xyz="0 0 0"
        rpy="0 0 0" />
      <geometry>
        <mesh
          filename="package://rohand_urdf_ros2/meshes_l//th_root_link.STL" />
      </geometry>
      <material
        name="">
        <color
          rgba="1 1 1 1" />
      </material>
    </visual>
    <collision>
      <origin
        xyz="0 0 0"
        rpy="0 0 0" />
      <geometry>
        <mesh
          filename="package://rohand_urdf_ros2/meshes_l//th_root_link.STL" />
      </geometry>
    </collision>
  </link>
  <joint
    name="th_root_link"
    type="revolute">
    <origin
      xyz="-0.0460801443059001 0.020015956388997 -0.023200337031876"
      rpy="0 -0.218406428574065 -0.0132452733633124" />
    <parent
      link="base_link" />
    <child
      link="th_root_link" />
    <axis
      xyz="-1 0 0" />
    <limit
      lower="-0.035"
      upper="1.605"
      effort="0"
      velocity="0" />
  </joint>
  <link
    name="th_proximal_link">
    <inertial>
      <origin
        xyz="-0.0180334098702285 0.00795834824716541 -0.000164754399991713"
        rpy="0 0 0" />
      <mass
        value="0.00666243139310216" />
      <inertia
        ixx="4.79346420364178E-07"
        ixy="4.90523711454142E-07"
        ixz="-1.1778308979192E-11"
        iyy="1.8864328702163E-06"
        iyz="-5.33955118540218E-11"
        izz="2.21297836984683E-06" />
    </inertial>
    <visual>
      <origin
        xyz="0 0 0"
        rpy="0 0 0" />
      <geometry>
        <mesh
          filename="package://rohand_urdf_ros2/meshes_l//th_proximal_link.STL" />
      </geometry>
      <material
        name="">
        <color
          rgba="1 1 1 1" />
      </material>
    </visual>
    <collision>
      <origin
        xyz="0 0 0"
        rpy="0 0 0" />
      <geometry>
        <mesh
          filename="package://rohand_urdf_ros2/meshes_l//th_proximal_link.STL" />
      </geometry>
    </collision>
  </link>
  <joint
    name="th_proximal_link"
    type="continuous">
    <origin
      xyz="-0.00675449620598668 0.0209804780594721 -0.00270002056556843"
      rpy="0 0 0.0129306539254238" />
    <parent
      link="th_root_link" />
    <child
      link="th_proximal_link" />
    <axis
      xyz="0 0 -1" />
  </joint>
  <link
    name="th_slider_link">
    <inertial>
      <origin
        xyz="0.00651851214500089 -0.00154139063852684 -4.96071095764522E-06"
        rpy="0 0 0" />
      <mass
        value="0.00106238517527826" />
      <inertia
        ixx="2.65429784332486E-08"
        ixy="-1.46074986229229E-09"
        ixz="-4.65128344147532E-12"
        iyy="8.00490417707624E-08"
        iyz="5.78948229675854E-11"
        izz="6.20054986046799E-08" />
    </inertial>
    <visual>
      <origin
        xyz="0 0 0"
        rpy="0 0 0" />
      <geometry>
        <mesh
          filename="package://rohand_urdf_ros2/meshes_l//th_slider_link.STL" />
      </geometry>
      <material
        name="">
        <color
          rgba="1 1 1 1" />
      </material>
    </visual>
    <collision>
      <origin
        xyz="0 0 0"
        rpy="0 0 0" />
      <geometry>
        <mesh
          filename="package://rohand_urdf_ros2/meshes_l//th_slider_link.STL" />
      </geometry>
    </collision>
  </link>
  <joint
    name="th_slider_link"
    type="prismatic">
    <origin
      xyz="-0.0108023937111218 0.00763873324235342 -0.000165316557534618"
      rpy="3.13838452099804 0 2.67784461906022" />
    <parent
      link="th_proximal_link" />
    <child
      link="th_slider_link" />
    <axis
      xyz="1 0 0" />
    <limit
      lower="-0.003"
      upper="0.008"
      effort="0"
      velocity="0" />
  </joint>
  <link
    name="th_connecting_link">
    <inertial>
      <origin
        xyz="-0.00451244324619419 0.00144325709917686 -6.77059325361155E-05"
        rpy="0 0 0" />
      <mass
        value="0.000339219041152736" />
      <inertia
        ixx="2.37331172107751E-09"
        ixy="8.11735483788056E-10"
        ixz="-5.04527750329156E-14"
        iyy="5.46165781545796E-09"
        iyz="2.24262219902211E-14"
        izz="5.08100814844394E-09" />
    </inertial>
    <visual>
      <origin
        xyz="0 0 0"
        rpy="0 0 0" />
      <geometry>
        <mesh
          filename="package://rohand_urdf_ros2/meshes_l//th_connecting_link.STL" />
      </geometry>
      <material
        name="">
        <color
          rgba="1 1 1 1" />
      </material>
    </visual>
    <collision>
      <origin
        xyz="0 0 0"
        rpy="0 0 0" />
      <geometry>
        <mesh
          filename="package://rohand_urdf_ros2/meshes_l//th_connecting_link.STL" />
      </geometry>
    </collision>
  </link>
  <joint
    name="th_connecting_link"
    type="continuous">
    <origin
      xyz="0.030299999929101 0.000160459585977893 -0.000142999395914452"
      rpy="3.13872334945882 -0.00143499623046761 2.67784667779356" />
    <parent
      link="th_slider_link" />
    <child
      link="th_connecting_link" />
    <axis
      xyz="0 0 -1" />
  </joint>
  <link
    name="th_distal_link">
    <inertial>
      <origin
        xyz="-0.00825361677819245 0.00781057568144408 0.00189926226365248"
        rpy="0 0 0" />
      <mass
        value="0.00503402601517063" />
      <inertia
        ixx="1.9936366479274E-07"
        ixy="5.81205161761473E-08"
        ixz="-5.87914433916686E-12"
        iyy="2.67949244844257E-07"
        iyz="1.69507543914536E-12"
        izz="2.35218960123074E-07" />
    </inertial>
    <visual>
      <origin
        xyz="0 0 0"
        rpy="0 0 0" />
      <geometry>
        <mesh
          filename="package://rohand_urdf_ros2/meshes_l//th_distal_link.STL" />
      </geometry>
      <material
        name="">
        <color
          rgba="1 1 1 1" />
      </material>
    </visual>
    <collision>
      <origin
        xyz="0 0 0"
        rpy="0 0 0" />
      <geometry>
        <mesh
          filename="package://rohand_urdf_ros2/meshes_l//th_distal_link.STL" />
      </geometry>
    </collision>
  </link>
  <joint
    name="th_distal_link"
    type="continuous">
    <origin
      xyz="-0.050881 0.013011 -0.0020153"
      rpy="0 0 0" />
    <parent
      link="th_proximal_link" />
    <child
      link="th_distal_link" />
    <axis
      xyz="0 0 -1" />
  </joint>
</robot>
